Workbook

Sheet Plan de costos
H2: Egresos
A3: Costos RRHH | B3: Personal | C3: Pago x hora | D3: Aguinaldo | E3: Cantidad horas | F3: Total | H3: Item | I3: Total
A4: Scrum Master | B4: Francisca Espinosa | C4: 13000 | D4: 100000 | E4: 250 | F4: =(E4*C4)+D4 -> 3350000 | H4: Costos RRHH | I4: =F4+F5+F6+F7+$F$8 -> 18060000
A5: Desarrollador | B5: Felipe González | C5: 12000 | D5: 100000 | E5: 600 | F5: =E5*C5+D5 -> 7300000 | H5: Equipos e infraestructura | I5: =E12+E13+E14+E17 -> 2250000
A6: Ing. Base de datos | B6: Felipe González | C6: 12000 | D6: 50000 | E6: 200 | F6: =E6*C6+D6 -> 2450000 | H6: Gastos generales e improvistos | I6: =D20+D21+D22+D23 -> 6570000
A7: Responsable de calidad | B7: Francisca Espinosa | C7: 10000 | D7: 50000 | E7: 180 | F7: =E7*C7+D7 -> 1850000 | H7: Gastos comunes | I7: =D26+D27+D28+D29 -> 530000
A8: Diseñador | B8: Francisca Espinosa | C8: 10000 | D8: 50000 | E8: 306 | F8: =E8*C8+D8 -> 3110000 | I8: =I4+I5+I6+I7 -> 27410000
K10: Egresos | L10: Total
A11: Equipos e infraestructura | B11: Descripción | C11: Costo unitario o por mes | D11: Cantidad unidad o mes | E11: Total | K11: Costos RRHH | L11: =F4+F5+F6+F7+$F$8 -> 18060000
A12: Notebooks | B12: Equipos desarrollo | C12: 649990 | D12: 2 | E12: =C12*D12 -> 1299980 | K12: Equipos e infraestructura | L12: =E12+E13+E14+E17 -> 2250000
A13: Smartphone test | B13: android para pruebas App | C13: 149990 | D13: 1 | E13: =C13*D13 -> 149990 | K13: Gastos generales e improvistos | L13: =D20+D21+D22+D23 -> 6570000
A14: Servidor y licencias | B14: Hosting y pagos | C14: 60000 | D14: 5 | E14: =C14*D14 -> 300000 | K14: Gastos comunes | L14: =D26+D27+D28+D29 -> 530000
A15: Perifericos | B15: Mouse y teclado | C15: 29990 | D15: 2 | E15: =C15*D15 -> 59980 | K15: Total egresos | L15: =L11+L12+L13+L14 -> 27410000
A16: Sillas de escritorio | B16: Ergonómicas | C16: 45000 | D16: 2 | E16: =C16*D16 -> 90000
A17: Oficina | B17: Lugar de desarrollo y reunion | C17: 100006 | D17: 5 | E17: =C17*D17 -> 500030
A19: Gastos generales e imprevistos | B19: Precio unitario | C19: Cantidad | D19: Total
A20: Transporte | B20: 1600 | C20: =140*5 -> 700 | D20: =C20*B20 -> 1120000
A21: Desayuno | B21: 2500 | C21: =70*5 -> 350 | D21: =C21*B21 -> 875000
A22: Almuerzo | B22: 4500 | C22: =70*5 -> 350 | D22: =C22*B22 -> 1575000
A23: Reserva de emergencia | B23: 3000000 | C23: 1 | D23: =C23*B23 -> 3000000
A25: Gastos comunes | B25: Precio unitario | C25: Cantidad de meses | D25: Total
A26: Agua | B26: 20000 | C26: 5 | D26: =C26*B26 -> 100000
A27: Luz | B27: 35000 | C27: 5 | D27: =C27*B27 -> 175000
A28: Gas | B28: 15000 | C28: 5 | D28: =C28*B28 -> 75000
A29: Internet | B29: 36000 | C29: 5 | D29: =C29*B29 -> 180000

Sheet Flujo de caja
A1: Antedecentes | E1: Tasa Mensual 1% | R1: Inversion | S1: =-B4 -> -28000000
A2: Presupuesto | B2: 35000000 | D2: EL PRESTAMO SE COMIENZA A PAGAR EL TERCER MES Y SE TERMINA DE PAGAR EN EL MES 14 | R2: Flujo 1 | S2: =B24 -> 27588000
A3: Costo del proyecto | B3: =SUM('Plan de costos'!I4:I7) -> 27410000 | R3: Flujo 2 | S3: =C24 -> -4562000
A4: Prestamo a solicitar | B4: 28000000 | R4: Flujo 3 | S4: =D24 -> 1484163
R5: Flujo 4 | S5: =E24 -> -7265837
R6: Flujo 5 | S6: =F24 -> 10234163
B7: Mes 1 | C7: Mes 2 | D7: Mes 3 | E7: Mes 4 | F7: Mes 5 | G7: Mes 6 | H7: Mes 7 | I7: Mes 8 | J7: Mes 9 | K7: Mes 10 | L7: Mes 11 | M7: Mes 12 | N7: Mes 13 | O7: Mes 14 | P7: Total | R7: Flujo 6 | S7: =G24 -> -2703837
A8: Egresos | R8: Flujo 7 | S8: =H24 -> -2703837
A9: Costos RRHH | B9: ='Plan de costos'!I4/5 -> 3612000 | C9: ='Plan de costos'!I4/5 -> 3612000 | D9: ='Plan de costos'!I4/5 -> 3612000 | E9: ='Plan de costos'!I4/5 -> 3612000 | F9: ='Plan de costos'!I4/5 -> 3612000 | G9: 0 | H9: 0 | I9: 0 | J9: 0 | K9: 0 | L9: 0 | M9: 0 | N9: 0 | O9: 0 | P9: =SUM(B9:O9) -> 18060000 | R9: Flujo 8 | S9: =I24 -> -2703837
A10: Equipos e infraestructura | B10: 1730000 | C10: 130000 | D10: 130000 | E10: 130000 | F10: 130000 | G10: 0 | H10: 0 | I10: 0 | J10: 0 | K10: 0 | L10: 0 | M10: 0 | N10: 0 | O10: 0 | P10: =SUM(B10:O10) -> 2250000 | R10: Flujo 9 | S10: =J24 -> -2703837
A11: Gastos generales e improvistos | B11: 3714000 | C11: 714000 | D11: 714000 | E11: 714000 | F11: 714000 | G11: 0 | H11: 0 | I11: 0 | J11: 0 | K11: 0 | L11: 0 | M11: 0 | N11: 0 | O11: 0 | P11: =SUM(B11:O11) -> 6570000 | R11: Flujo 10 | S11: =K24 -> -2703837
A12: Gastos comunes | B12: ='Plan de costos'!$I$7/5 -> 106000 | C12: ='Plan de costos'!$I$7/5 -> 106000 | D12: ='Plan de costos'!$I$7/5 -> 106000 | E12: ='Plan de costos'!$I$7/5 -> 106000 | F12: ='Plan de costos'!$I$7/5 -> 106000 | G12: 0 | H12: 0 | I12: 0 | J12: 0 | K12: 0 | L12: 0 | M12: 0 | N12: 0 | O12: 0 | P12: =SUM(B12:O12) -> 530000 | R12: Flujo 11 | S12: =L24 -> -2703837
A13: Pago credito | B13: 0 | C13: 0 | D13: 2703837 | E13: 2703837 | F13: 2703837 | G13: 2703837 | H13: 2703837 | I13: 2703837 | J13: 2703837 | K13: 2703837 | L13: 2703837 | M13: 2703837 | N13: 2703837 | O13: 2703837 | P13: =SUM(D13:O13) -> 32446044 | R13: Flujo 12 | S13: =M24 -> -2703837
A14: Total egresos | B14: =SUM(B9:B13) -> 9162000 | C14: =SUM(C9:C13) -> 4562000 | D14: =SUM(D9:D13) -> 7265837 | E14: =SUM(E9:E13) -> 7265837 | F14: =SUM(F9:F13) -> 7265837 | G14: =SUM(G9:G13) -> 2703837 | H14: =SUM(H9:H13) -> 2703837 | I14: =SUM(I9:I13) -> 2703837 | ... O14: =SUM(O9:O13) -> 2703837 | R14: Flujo 13 | S14: =N24 -> -2703837
R15: Flujo 14 | S15: =O24 -> -2703837
A16: Se acordó con el cliente realizar el pago del proyecto en 3 cuotas, la primera el inicio del mismo de un 25%, la segunda en el tercer mes de 25%, y la ultima en la entrega del proyecto del 50%
A17: Ingresos
A18: Cuota 1 pago proyecto | B18: =B2*0.25 -> 8750000 | C18: 0 | G18: =0 -> 0 | H18: =0 -> 0 | I18: =0 -> 0 | J18: =0 -> 0 | K18: =0 -> 0 | L18: =0 -> 0 | M18: =0 -> 0 | N18: =0 -> 0 | O18: =0 -> 0
A19: Cuota 2 pago proyecto | D19: =B2*0.25 -> 8750000 | G19: =0 -> 0 | H19: =0 -> 0 | I19: =0 -> 0 | J19: =0 -> 0 | K19: =0 -> 0 | L19: =0 -> 0 | M19: =0 -> 0 | N19: =0 -> 0 | O19: =0 -> 0 | R19: Tasa de descuento | S19: 0.01 | T19: Mensual
A20: Cuota 3 pago proyecto | F20: =B2*0.5 -> 17500000 | G20: =0 -> 0 | H20: =0 -> 0 | I20: =0 -> 0 | J20: =0 -> 0 | K20: =0 -> 0 | L20: =0 -> 0 | M20: =0 -> 0 | N20: =0 -> 0 | O20: =0 -> 0
A21: Prestamo | B21: =B4 -> 28000000 | G21: =0 -> 0 | H21: =0 -> 0 | I21: =0 -> 0 | J21: =0 -> 0 | K21: =0 -> 0 | L21: =0 -> 0 | M21: =0 -> 0 | N21: =0 -> 0 | O21: =0 -> 0 | R21: TIR | S21: 0.27 | T21: Rentabilidad Alta
A22: Total ingresos | B22: =B18+B4 -> 36750000 | C22: 0 | D22: =D19 -> 8750000 | E22: 0 | F22: =F20 -> 17500000 | G22: =0 -> 0 | H22: =0 -> 0 | I22: =0 -> 0 | J22: =0 -> 0 | K22: =0 -> 0 | L22: =0 -> 0 | M22: =0 -> 0 | N22: =0 -> 0 | O22: =0 -> 0 | R22: VAN | S22: =SUM(B24:O24) -> 3143956 | T22: El proyecto es rentablre
A24: Flujo | B24: =B22-B14 -> 27588000 | C24: =C22-C14 -> -4562000 | D24: =D22-D14 -> 1484163 | E24: =E22-E14 -> -7265837 | F24: =F22-F14 -> 10234163 | G24: =G22-G14 -> -2703837 | H24: =H22-H14 -> -2703837 | I24: =I22-I14 -> -2703837 | ... O24: =O22-O14 -> -2703837 | P24: =SUM(B24:O24) -> 3143956
A26: total semanas de trabajo | B26: 22
A27: horas de trabajo por semana | B27: 35 | C27: CADA UNO
A28: costo RRHH por semana | B28: ='Plan de costos'!I4/22 -> 820909.09
A29: gastos equipos e infraestructura | B29: ='Plan de costos'!I5 -> 2250000
A30: gastos generales e improvistos | B30: ='Plan de costos'!I6/22 -> 298636.36
O31: Tasa de interés Anual: 12% | R31: 0.12
A35: Egresos | H35: Antedecentes | K35: Dashboard
A36: Costos RRHH | B36: ='Plan de costos'!I4/5 -> 3612000 | C36: ='Plan de costos'!$I$4/5 -> 3612000 | D36: ='Plan de costos'!$I$4/5 -> 3612000 | E36: ='Plan de costos'!$I$4/5 -> 3612000 | F36: ='Plan de costos'!$I$4/5 -> 3612000 | H36: Presupuesto | I36: =B2 -> 35000000 | K36: Inversion | L36: =S1 -> -28000000
A37: Equipos e infraestructura | B37: 1730000 | C37: 130000 | D37: 130000 | E37: 130000 | F37: 130000 | H37: Costo del proyecto | I37: =B3 -> 27410000 | K37: Flujo 1 | L37: =S2 -> 27588000
A38: Gastos generales e improvistos | B38: 3714000 | C38: 714000 | D38: 714000 | E38: 714000 | F38: 714000 | H38: Prestamo a solicitar | I38: =B4 -> 28000000 | K38: Flujo 2 | L38: =S3 -> -4562000
A39: Gastos comunes | B39: ='Plan de costos'!$I$7/5 -> 106000 | C39: ='Plan de costos'!$I$7/5 -> 106000 | D39: ='Plan de costos'!$I$7/5 -> 106000 | E39: ='Plan de costos'!$I$7/5 -> 106000 | F39: ='Plan de costos'!$I$7/5 -> 106000 | K39: Flujo 3 | L39: =S4 -> 1484163
A40: Pago credito | D40: =D13 -> 2703837 | E40: =E13 -> 2703837 | F40: =F13 -> 2703837 | H40: Cuotas | I40: 12 | K40: Flujo 4 | L40: =S5 -> -7265837
A41: Total egresos | B41: =SUM(B36:B40) -> 9162000 | C41: =SUM(C36:C40) -> 4562000 | D41: =SUM(D36:D40) -> 7265837 | E41: =SUM(E36:E40) -> 7265837 | F41: =SUM(F36:F40) -> 7265837 | H41: Costo total crédito | I41: =P13 -> 32446044 | K41: Flujo 5 | L41: =S6 -> 10234163
A42: Ingresos | H42: Valor Cuota | I42: =O13 -> 2703837 | K42: Tasa de descuento | L42: =S19 -> 0.01
A43: Cuota 1 pago proyecto | B43: =B2*0.25 -> 8750000 | H43: Interés Bancario | I43: =I41-I38 -> 4446044 | K43: TIR | L43: =S21 -> 0.27
A44: Cuota 2 pago proyecto | D44: =B2*0.25 -> 8750000 | H44: Interés anual | I44: =R31 -> 0.12 | K44: VAN | L44: =S22 -> 3143956
A45: Cuota 3 pago proyecto | F45: =B2*0.5 -> 17500000
...
